<?xml version="1.0" ?>
<robot name="hexapod">

  <!-- Body (Main Torso) -->
  <link name="body">
    <visual>
      <geometry>
        <box size="0.18 0.12 0.01"/>
      </geometry>
      <material name="yellow">
        <color rgba="1 0.5 0 1.0"/>
      </material>
      <origin xyz="0 0 0" rpy="0 0 0"/>
    </visual>
    <collision>
      <geometry>
        <box size="0.18 0.12 0.01"/>
      </geometry>
      <origin xyz="0 0 0" rpy="0 0 0"/>
    </collision>
    <inertial>
      <mass value="5.0"/>
      <inertia ixx="0.1" ixy="0" ixz="0" iyy="0.1" iyz="0" izz="0.1"/>
    </inertial>
  </link>

  <!-- Base Link -->
  <link name="base_link">
    <inertial>
      <origin xyz="0 0 0" rpy="0 0 0"/>
      <mass value="2.0"/>
      <inertia ixx="0.05" ixy="0.0" ixz="0.0"
              iyy="0.05" iyz="0.0"
              izz="0.05"/>
    </inertial>
  </link>

  <!-- Joint between base_link and body -->
  <joint name="body_joint" type="fixed">
    <parent link="base_link"/>
    <child link="body"/>
    <origin xyz="0 0 0" rpy="0 0 0"/>
  </joint>

  <!-- Leg 1 -->
  <link name="coxa1">
  <visual>
      <geometry>
        <box size="0.01 0.01 0.01"/>
      </geometry>
      <material name="orange">
        <color rgba="1 0.5 0 1.0"/>
      </material>
      <origin xyz="0 0 0" rpy="0 0 0"/>
    </visual>
    <collision>
      <geometry>
        <box size="0.01 0.01 0.01"/>
      </geometry>
      <origin xyz="0 0 0" rpy="0 0 0"/>
    </collision>
    <inertial>
      <mass value="1.0"/>
      <inertia ixx="0.0001" ixy="0" ixz="0" iyy="0.0001" iyz="0" izz="0.0001"/>
    </inertial>
  </link>

  <joint name="coxa_joint1" type="revolute">
    <parent link="base_link"/>
    <child link="coxa1"/>
    <origin xyz="0.09 0.06 0" rpy="0 0 0"/>
    <axis xyz="0 0 1"/>
    <limit lower="0" upper="3.14" effort="1" velocity="1"/>
  </joint>

  <link name="femur1">
    <visual>
      <geometry>
        <box size="0.06 0.01 0.01"/>
      </geometry>
      <material name="orange">
        <color rgba="1 0.5 0 1.0"/>
      </material>
      <origin xyz="0.03 0 0" rpy="0 0 0"/>
    </visual>
    <collision>
      <geometry>
        <box size="0.06 0.01 0.01"/>
      </geometry>
      <origin xyz="0.03 0 0" rpy="0 0 0"/>
    </collision>
    <inertial>
      <mass value="1.0"/>
      <inertia ixx="0.0001" ixy="0" ixz="0" iyy="0.0001" iyz="0" izz="0.0001"/>
    </inertial>
  </link>

  <joint name="femur_joint1" type="revolute">
    <parent link="coxa1"/>
    <child link="femur1"/>
    <origin xyz="0.005 0 0" rpy="0 -1.57 0"/>
    <axis xyz="0 1 0"/>
    <limit lower="0" upper="3.14" effort="1" velocity="1"/>
  </joint>

  <link name="tibia1">
    <visual>
      <geometry>
        <box size="0.06 0.01 0.01"/>
      </geometry>
      <material name="orange">
        <color rgba="1 0.5 0 1.0"/>
      </material>
      <origin xyz="0.03 0 0" rpy="0 0 0"/>
    </visual>
    <collision>
      <geometry>
        <box size="0.06 0.01 0.01"/>
      </geometry>
      <origin xyz="0.03 0 0" rpy="0 0 0"/>
    </collision>
    <inertial>
      <mass value="1.0"/>
      <inertia ixx="0.0001" ixy="0" ixz="0" iyy="0.0001" iyz="0" izz="0.0001"/>
    </inertial>
  </link>

  <joint name="tibia_joint1" type="revolute">
    <parent link="femur1"/>
    <child link="tibia1"/>
    <origin xyz="0.06 0 0" rpy="0 0 0"/>
    <axis xyz="0 1 0"/>
    <limit lower="0" upper="3.14" effort="1" velocity="1"/>
  </joint>

  <!-- Leg 2 -->
  <link name="coxa2">
  <visual>
      <geometry>
        <box size="0.01 0.01 0.01"/>
      </geometry>
      <material name="orange">
        <color rgba="1 0.5 0 1.0"/>
      </material>
      <origin xyz="0 0 0" rpy="0 0 0"/>
    </visual>
    <collision>
      <geometry>
        <box size="0.01 0.01 0.01"/>
      </geometry>
      <origin xyz="0 0 0" rpy="0 0 0"/>
    </collision>
    <inertial>
      <mass value="1.0"/>
      <inertia ixx="0.0001" ixy="0" ixz="0" iyy="0.0001" iyz="0" izz="0.0001"/>
    </inertial>
  </link>

  <joint name="coxa_joint2" type="revolute">
    <parent link="base_link"/>
    <child link="coxa2"/>
    <origin xyz="0 0.06 0" rpy="0 0 0"/>
    <axis xyz="0 0 1"/>
    <limit lower="0" upper="3.14" effort="1" velocity="1"/>
  </joint>

  <link name="femur2">
    <visual>
      <geometry>
        <box size="0.06 0.01 0.01"/>
      </geometry>
      <material name="orange">
        <color rgba="1 0.5 0 1.0"/>
      </material>
      <origin xyz="0.03 0 0" rpy="0 0 0"/>
    </visual>
    <collision>
      <geometry>
        <box size="0.06 0.01 0.01"/>
      </geometry>
      <origin xyz="0.03 0 0" rpy="0 0 0"/>
    </collision>
    <inertial>
      <mass value="1.0"/>
      <inertia ixx="0.0001" ixy="0" ixz="0" iyy="0.0001" iyz="0" izz="0.0001"/>
    </inertial>
  </link>

  <joint name="femur_joint2" type="revolute">
    <parent link="coxa2"/>
    <child link="femur2"/>
    <origin xyz="0.005 0 0" rpy="0 -1.57 0"/>
    <axis xyz="0 1 0"/>
    <limit lower="0" upper="3.14" effort="1" velocity="1"/>
  </joint>

  <link name="tibia2">
    <visual>
      <geometry>
        <box size="0.06 0.01 0.01"/>
      </geometry>
      <material name="orange">
        <color rgba="1 0.5 0 1.0"/>
      </material>
      <origin xyz="0.03 0 0" rpy="0 0 0"/>
    </visual>
    <collision>
      <geometry>
        <box size="0.06 0.01 0.01"/>
      </geometry>
      <origin xyz="0.03 0 0" rpy="0 0 0"/>
    </collision>
    <inertial>
      <mass value="1.0"/>
      <inertia ixx="0.0001" ixy="0" ixz="0" iyy="0.0001" iyz="0" izz="0.0001"/>
    </inertial>
  </link>

  <joint name="tibia_joint2" type="revolute">
    <parent link="femur2"/>
    <child link="tibia2"/>
    <origin xyz="0.06 0 0" rpy="0 0 0"/>
    <axis xyz="0 1 0"/>
    <limit lower="0" upper="3.14" effort="1" velocity="1"/>
  </joint>

  <!-- Leg 3 -->
  <link name="coxa3">
  <visual>
      <geometry>
        <box size="0.01 0.01 0.01"/>
      </geometry>
      <material name="orange">
        <color rgba="1 0.5 0 1.0"/>
      </material>
      <origin xyz="0 0 0" rpy="0 0 0"/>
    </visual>
    <collision>
      <geometry>
        <box size="0.01 0.01 0.01"/>
      </geometry>
      <origin xyz="0 0 0" rpy="0 0 0"/>
    </collision>
    <inertial>
      <mass value="1.0"/>
      <inertia ixx="0.0001" ixy="0" ixz="0" iyy="0.0001" iyz="0" izz="0.0001"/>
    </inertial>
  </link>

  <joint name="coxa_joint3" type="revolute">
    <parent link="base_link"/>
    <child link="coxa3"/>
    <origin xyz="-0.09 0.06 0" rpy="0 0 0"/>
    <axis xyz="0 0 1"/>
    <limit lower="0" upper="3.14" effort="1" velocity="1"/>
  </joint>

  <link name="femur3">
    <visual>
      <geometry>
        <box size="0.06 0.01 0.01"/>
      </geometry>
      <material name="orange">
        <color rgba="1 0.5 0 1.0"/>
      </material>
      <origin xyz="0.03 0 0" rpy="0 0 0"/>
    </visual>
    <collision>
      <geometry>
        <box size="0.06 0.01 0.01"/>
      </geometry>
      <origin xyz="0.03 0 0" rpy="0 0 0"/>
    </collision>
    <inertial>
      <mass value="1.0"/>
      <inertia ixx="0.0001" ixy="0" ixz="0" iyy="0.0001" iyz="0" izz="0.0001"/>
    </inertial>
  </link>

  <joint name="femur_joint3" type="revolute">
    <parent link="coxa3"/>
    <child link="femur3"/>
    <origin xyz="0.005 0 0" rpy="0 -1.57 0"/>
    <axis xyz="0 1 0"/>
    <limit lower="0" upper="3.14" effort="1" velocity="1"/>
  </joint>

  <link name="tibia3">
    <visual>
      <geometry>
        <box size="0.06 0.01 0.01"/>
      </geometry>
      <material name="orange">
        <color rgba="1 0.5 0 1.0"/>
      </material>
      <origin xyz="0.03 0 0" rpy="0 0 0"/>
    </visual>
    <collision>
      <geometry>
        <box size="0.06 0.01 0.01"/>
      </geometry>
      <origin xyz="0.03 0 0" rpy="0 0 0"/>
    </collision>
    <inertial>
      <mass value="1.0"/>
      <inertia ixx="0.0001" ixy="0" ixz="0" iyy="0.0001" iyz="0" izz="0.0001"/>
    </inertial>
  </link>

  <joint name="tibia_joint3" type="revolute">
    <parent link="femur3"/>
    <child link="tibia3"/>
    <origin xyz="0.06 0 0" rpy="0 0 0"/>
    <axis xyz="0 1 0"/>
    <limit lower="0" upper="3.14" effort="1" velocity="1"/>
  </joint>

  <!-- Leg 4 -->
  <link name="coxa4">
  <visual>
      <geometry>
        <box size="0.01 0.01 0.01"/>
      </geometry>
      <material name="orange">
        <color rgba="1 0.5 0 1.0"/>
      </material>
      <origin xyz="0 0 0" rpy="0 0 0"/>
    </visual>
    <collision>
      <geometry>
        <box size="0.01 0.01 0.01"/>
      </geometry>
      <origin xyz="0 0 0" rpy="0 0 0"/>
    </collision>
    <inertial>
      <mass value="1.0"/>
      <inertia ixx="0.0001" ixy="0" ixz="0" iyy="0.0001" iyz="0" izz="0.0001"/>
    </inertial>
  </link>

  <joint name="coxa_joint4" type="revolute">
    <parent link="base_link"/>
    <child link="coxa4"/>
    <origin xyz="-0.09 -0.06 0" rpy="0 0 3.14"/>
    <axis xyz="0 0 1"/>
    <limit lower="0" upper="3.14" effort="1" velocity="1"/>
  </joint>

  <link name="femur4">
    <visual>
      <geometry>
        <box size="0.06 0.01 0.01"/>
      </geometry>
      <material name="orange">
        <color rgba="1 0.5 0 1.0"/>
      </material>
      <origin xyz="0.03 0 0" rpy="0 0 0"/>
    </visual>
    <collision>
      <geometry>
        <box size="0.06 0.01 0.01"/>
      </geometry>
      <origin xyz="0.03 0 0" rpy="0 0 0"/>
    </collision>
    <inertial>
      <mass value="1.0"/>
      <inertia ixx="0.0001" ixy="0" ixz="0" iyy="0.0001" iyz="0" izz="0.0001"/>
    </inertial>
  </link>

  <joint name="femur_joint4" type="revolute">
    <parent link="coxa4"/>
    <child link="femur4"/>
    <origin xyz="0.005 0 0" rpy="0 -1.57 0"/>
    <axis xyz="0 1 0"/>
    <limit lower="0" upper="3.14" effort="1" velocity="1"/>
  </joint>

  <link name="tibia4">
    <visual>
      <geometry>
        <box size="0.06 0.01 0.01"/>
      </geometry>
      <material name="orange">
        <color rgba="1 0.5 0 1.0"/>
      </material>
      <origin xyz="0.03 0 0" rpy="0 0 0"/>
    </visual>
    <collision>
      <geometry>
        <box size="0.06 0.01 0.01"/>
      </geometry>
      <origin xyz="0.03 0 0" rpy="0 0 0"/>
    </collision>
    <inertial>
      <mass value="1.0"/>
      <inertia ixx="0.0001" ixy="0" ixz="0" iyy="0.0001" iyz="0" izz="0.0001"/>
    </inertial>
  </link>

  <joint name="tibia_joint4" type="revolute">
    <parent link="femur4"/>
    <child link="tibia4"/>
    <origin xyz="0.06 0 0" rpy="0 0 0"/>
    <axis xyz="0 1 0"/>
    <limit lower="0" upper="3.14" effort="1" velocity="1"/>
  </joint>

  <!-- Leg 5 -->
  <link name="coxa5">
  <visual>
      <geometry>
        <box size="0.01 0.01 0.01"/>
      </geometry>
      <material name="orange">
        <color rgba="1 0.5 0 1.0"/>
      </material>
      <origin xyz="0 0 0" rpy="0 0 0"/>
    </visual>
    <collision>
      <geometry>
        <box size="0.01 0.01 0.01"/>
      </geometry>
      <origin xyz="0 0 0" rpy="0 0 0"/>
    </collision>
    <inertial>
      <mass value="1.0"/>
      <inertia ixx="0.0001" ixy="0" ixz="0" iyy="0.0001" iyz="0" izz="0.0001"/>
    </inertial>
  </link>

  <joint name="coxa_joint5" type="revolute">
    <parent link="base_link"/>
    <child link="coxa5"/>
    <origin xyz="0 -0.06 0" rpy="0 0 3.14"/>
    <axis xyz="0 0 1"/>
    <limit lower="0" upper="3.14" effort="1" velocity="1"/>
  </joint>

  <link name="femur5">
    <visual>
      <geometry>
        <box size="0.06 0.01 0.01"/>
      </geometry>
      <material name="orange">
        <color rgba="1 0.5 0 1.0"/>
      </material>
      <origin xyz="0.03 0 0" rpy="0 0 0"/>
    </visual>
    <collision>
      <geometry>
        <box size="0.06 0.01 0.01"/>
      </geometry>
      <origin xyz="0.03 0 0" rpy="0 0 0"/>
    </collision>
    <inertial>
      <mass value="1.0"/>
      <inertia ixx="0.0001" ixy="0" ixz="0" iyy="0.0001" iyz="0" izz="0.0001"/>
    </inertial>
  </link>

  <joint name="femur_joint5" type="revolute">
    <parent link="coxa5"/>
    <child link="femur5"/>
    <origin xyz="0.005 0 0" rpy="0 -1.57 0"/>
    <axis xyz="0 1 0"/>
    <limit lower="0" upper="3.14" effort="1" velocity="1"/>
  </joint>

  <link name="tibia5">
    <visual>
      <geometry>
        <box size="0.06 0.01 0.01"/>
      </geometry>
      <material name="orange">
        <color rgba="1 0.5 0 1.0"/>
      </material>
      <origin xyz="0.03 0 0" rpy="0 0 0"/>
    </visual>
    <collision>
      <geometry>
        <box size="0.06 0.01 0.01"/>
      </geometry>
      <origin xyz="0.03 0 0" rpy="0 0 0"/>
    </collision>
    <inertial>
      <mass value="1.0"/>
      <inertia ixx="0.0001" ixy="0" ixz="0" iyy="0.0001" iyz="0" izz="0.0001"/>
    </inertial>
  </link>

  <joint name="tibia_joint5" type="revolute">
    <parent link="femur5"/>
    <child link="tibia5"/>
    <origin xyz="0.06 0 0" rpy="0 0 0"/>
    <axis xyz="0 1 0"/>
    <limit lower="0" upper="3.14" effort="1" velocity="1"/>
  </joint>

  <!-- Leg 6 -->
  <link name="coxa6">
  <visual>
      <geometry>
        <box size="0.01 0.01 0.01"/>
      </geometry>
      <material name="orange">
        <color rgba="1 0.5 0 1.0"/>
      </material>
      <origin xyz="0 0 0" rpy="0 0 0"/>
    </visual>
    <collision>
      <geometry>
        <box size="0.01 0.01 0.01"/>
      </geometry>
      <origin xyz="0 0 0" rpy="0 0 0"/>
    </collision>
    <inertial>
      <mass value="1.0"/>
      <inertia ixx="0.0001" ixy="0" ixz="0" iyy="0.0001" iyz="0" izz="0.0001"/>
    </inertial>
  </link>

  <joint name="coxa_joint6" type="revolute">
    <parent link="base_link"/>
    <child link="coxa6"/>
    <origin xyz="0.09 -0.06 0" rpy="0 0 3.14"/>
    <axis xyz="0 0 1"/>
    <limit lower="0" upper="3.14" effort="1" velocity="1"/>
  </joint>

  <link name="femur6">
    <visual>
      <geometry>
        <box size="0.06 0.01 0.01"/>
      </geometry>
      <material name="orange">
        <color rgba="1 0.5 0 1.0"/>
      </material>
      <origin xyz="0.03 0 0" rpy="0 0 0"/>
    </visual>
    <collision>
      <geometry>
        <box size="0.06 0.01 0.01"/>
      </geometry>
      <origin xyz="0.03 0 0" rpy="0 0 0"/>
    </collision>
    <inertial>
      <mass value="1.0"/>
      <inertia ixx="0.0001" ixy="0" ixz="0" iyy="0.0001" iyz="0" izz="0.0001"/>
    </inertial>
  </link>

  <joint name="femur_joint6" type="revolute">
    <parent link="coxa6"/>
    <child link="femur6"/>
    <origin xyz="0.005 0 0" rpy="0 -1.57 0"/>
    <axis xyz="0 1 0"/>
    <limit lower="0" upper="3.14" effort="1" velocity="1"/>
  </joint>

  <link name="tibia6">
    <visual>
      <geometry>
        <box size="0.06 0.01 0.01"/>
      </geometry>
      <material name="orange">
        <color rgba="1 0.5 0 1.0"/>
      </material>
      <origin xyz="0.03 0 0" rpy="0 0 0"/>
    </visual>
    <collision>
      <geometry>
        <box size="0.06 0.01 0.01"/>
      </geometry>
      <origin xyz="0.03 0 0" rpy="0 0 0"/>
    </collision>
    <inertial>
      <mass value="1.0"/>
      <inertia ixx="0.0001" ixy="0" ixz="0" iyy="0.0001" iyz="0" izz="0.0001"/>
    </inertial>
  </link>

  <joint name="tibia_joint6" type="revolute">
    <parent link="femur6"/>
    <child link="tibia6"/>
    <origin xyz="0.06 0 0" rpy="0 0 0"/>
    <axis xyz="0 1 0"/>
    <limit lower="0" upper="3.14" effort="1" velocity="1"/>
  </joint>

</robot>
